// what is the output? and explain why?

// 1
Promise.resolve(1)
  .then(res => {
    console.log(res);
    return 2;
  })
  .catch(err => {
    return 3;
  })
  .then(res => {
    console.log(res);
  });
//1 2, it resolve successfully, so 3 will not print

// // 2
Promise.reject(1)
  .then(res => {
    console.log(res);
    return 2;
  })
  .catch(err => {
    console.log(err);
    return 3;
  })
  .then(res => {
    console.log(res);
  });// 1 3, it's rejected so then will not excute, it will excute catch.

//3
function runAsync(x) {
  const p = new Promise(resolve =>
    setTimeout(() => resolve(x), 1000)
  );
  return p;
}

function runReject(x) {
  const p = new Promise((resolve, reject) =>
    setTimeout(() => reject(`Error: ${x}`), 1000 * x)
  );
  return p;
}

Promise.all([runAsync(1), runReject(4), runAsync(3), runReject(2)])
  .then(res => console.log(res))
  .catch(err => console.log(err));
//Error: 4 Error: 2, because all take all promises, then excutes only all promises resolve successfully
//but there are 2 reject promises, so All Promises will reject and excute catch